<?xml version="1.0"?>
<robot name="robot" xmlns:xacro="http://www.ros.org/wiki/xacro">
    <!-- Gazebo plugin for ros2_control -->
    <gazebo>
        <plugin name="gazebo_ros2_control" filename="libgazebo_ros2_control.so">
            <parameters>$(find robot_description)/config/controllers.yaml</parameters>
        </plugin>
    </gazebo>

    <material name="grey">
        <color rgba="0.7 0.7 0.7 1"/>
    </material>

    <material name="blue">
        <color rgba="0 0 0.6 1"/>
    </material>

    <material name="white">
        <color rgba="1 1 1 1"/>
    </material>

    <!-- Gazebo material properties -->
    <gazebo reference="base_link">
        <material>Gazebo/Blue</material>
        <mu1>0.2</mu1>
        <mu2>0.2</mu2>
    </gazebo>

    <gazebo reference="left_b_wheel">
        <material>Gazebo/White</material>
        <mu1>1.0</mu1>
        <mu2>1.0</mu2>
    </gazebo>

    <gazebo reference="left_f_wheel">
        <material>Gazebo/White</material>
        <mu1>1.0</mu1>
        <mu2>1.0</mu2>
    </gazebo>

    <gazebo reference="right_b_wheel">
        <material>Gazebo/White</material>
        <mu1>1.0</mu1>
        <mu2>1.0</mu2>
    </gazebo>

    <gazebo reference="right_f_wheel">
        <material>Gazebo/White</material>
        <mu1>1.0</mu1>
        <mu2>1.0</mu2>
    </gazebo>

    <link name="base_footprint"/>

    <link name="base_link">
        <visual>
            <geometry>
                <box size="0.6 0.4 0.2"/>
            </geometry>
            <origin xyz="0 0 0.1" rpy="0 0 0"/>
            <material name="blue"/>
        </visual>
        <collision>
            <geometry>
                <box size="0.6 0.4 0.2"/>
            </geometry>
            <origin xyz="0 0 0.1" rpy="0 0 0"/>
        </collision>
        <inertial>
            <mass value="5.0"/>
            <origin xyz="0 0 0.1" rpy="0 0 0"/>
            <inertia ixx="0.0267" ixy="0" ixz="0" iyy="0.0217" iyz="0" izz="0.0133"/>
        </inertial>
    </link>

    <link name="left_b_wheel">
        <visual>
            <geometry>
                <cylinder radius="0.1" length="0.05"/>
            </geometry>
            <origin xyz="0 0 0" rpy="1.57 0 0"/>
            <material name="white"/>
        </visual>
        <collision>
            <geometry>
                <cylinder radius="0.1" length="0.05"/>
            </geometry>
            <origin xyz="0 0 0" rpy="1.57 0 0"/>
        </collision>
        <inertial>
            <mass value="1.0"/>
            <origin xyz="0 0 0" rpy="0 0 0"/>
            <inertia ixx="0.00054" ixy="0" ixz="0" iyy="0.00054" iyz="0" izz="0.005"/>
        </inertial>
    </link>

    <link name="left_f_wheel">
        <visual>
            <geometry>
                <cylinder radius="0.1" length="0.05"/>
            </geometry>
            <origin xyz="0 0 0" rpy="1.57 0 0"/>
            <material name="white"/>
        </visual>
        <collision>
            <geometry>
                <cylinder radius="0.1" length="0.05"/>
            </geometry>
            <origin xyz="0 0 0" rpy="1.57 0 0"/>
        </collision>
        <inertial>
            <mass value="1.0"/>
            <origin xyz="0 0 0" rpy="0 0 0"/>
            <inertia ixx="0.00054" ixy="0" ixz="0" iyy="0.00054" iyz="0" izz="0.005"/>
        </inertial>
    </link>

    <link name="right_b_wheel">
        <visual>
            <geometry>
                <cylinder radius="0.1" length="0.05"/>
            </geometry>
            <origin xyz="0 0 0" rpy="1.57 0 0"/>
            <material name="white"/>
        </visual>
        <collision>
            <geometry>
                <cylinder radius="0.1" length="0.05"/>
            </geometry>
            <origin xyz="0 0 0" rpy="1.57 0 0"/>
        </collision>
        <inertial>
            <mass value="1.0"/>
            <origin xyz="0 0 0" rpy="0 0 0"/>
            <inertia ixx="0.00054" ixy="0" ixz="0" iyy="0.00054" iyz="0" izz="0.005"/>
        </inertial>
    </link>

    <link name="right_f_wheel">
        <visual>
            <geometry>
                <cylinder radius="0.1" length="0.05"/>
            </geometry>
            <origin xyz="0 0 0" rpy="1.57 0 0"/>
            <material name="white"/>
        </visual>
        <collision>
            <geometry>
                <cylinder radius="0.1" length="0.05"/>
            </geometry>
            <origin xyz="0 0 0" rpy="1.57 0 0"/>
        </collision>
        <inertial>
            <mass value="1.0"/>
            <origin xyz="0 0 0" rpy="0 0 0"/>
            <inertia ixx="0.00054" ixy="0" ixz="0" iyy="0.00054" iyz="0" izz="0.005"/>
        </inertial>
    </link>

    <joint name="base_joint" type="fixed">
        <parent link="base_footprint"/>
        <child link="base_link"/>
        <origin xyz="0 0 0.1" rpy="0 0 0"/>
    </joint>

    <joint name="base_left_b_wheel_joint" type="continuous">
        <parent link="base_link"/>
        <child link="left_b_wheel"/>
        <origin xyz="-0.15 0.225 0" rpy="0 0 0"/>
        <axis xyz="0 1 0"/>
        <dynamics damping="0.1" friction="0.1"/>
    </joint>

    <joint name="base_left_f_wheel_joint" type="continuous">
        <parent link="base_link"/>
        <child link="left_f_wheel"/>
        <origin xyz="0.15 0.225 0" rpy="0 0 0"/>
        <axis xyz="0 1 0"/>
        <dynamics damping="0.1" friction="0.1"/>
    </joint>

    <joint name="base_right_b_wheel_joint" type="continuous">
        <parent link="base_link"/>
        <child link="right_b_wheel"/>
        <origin xyz="-0.15 -0.225 0" rpy="0 0 0"/>
        <axis xyz="0 1 0"/>
        <dynamics damping="0.1" friction="0.1"/>
    </joint>

    <joint name="base_right_f_wheel_joint" type="continuous">
        <parent link="base_link"/>
        <child link="right_f_wheel"/>
        <origin xyz="0.15 -0.225 0" rpy="0 0 0"/>
        <axis xyz="0 1 0"/>
        <dynamics damping="0.1" friction="0.1"/>
    </joint>

</robot>